Workbook

Sheet Readme
A1: Objais formal revenue model
A3: Evidence status | B3: ALL numerical inputs are illustrative assumptions, not Objais results, prices, contracts or forecasts.
A4: Mathematical source | B4: Objais Revenue Model.tex contains definitions, derivations and limits. revenue_model.py is the executable reference.
A5: What this file does | B5: Six synthetic architectures, editable parameters and live 36-month expected-value formulas; native currency EUR for every example.
A6: Edit | B6: Blue cells on Parameters are inputs. Formula-derived initial payments are not blue. Each S sheet has calendar and single-acquired-owner blocks.
A7: Opportunity states | B7: E: retained owner with one unexhausted opportunity. M: retained owner after monetisation. State continuation is distinct from policy survival and billing continuation.
A8: q definition | B8: Probability of the first payable monetary event per eligible owner-month; lead acceptance in S1-S5 and policy binding in S6. Do not reuse an observed rate across these definitions.
A9: Repeat eligibility | B9: Reset probability is a genuinely new payable opportunity, not another app visit, record, scan or automatic policy revaluation.
A10: Initial payment | B10: Lead case: stated fee. Binding case: eligible premium times commission rate times retained share. Architectures are alternatives; no lead+binding double counting.
A11: Other streams | B11: Software and annual renewal hypotheses are separate. Lead-only architecture does not earn renewal income. Service-referral events exist in the formal specification but are not simulated here.
A12: Time convention | B12: Acquisition and monetisation during month; retention and eligibility reset at month end. New software pays in month of acquisition; first annual renewal is month 13.
A13: Cost convention | B13: Eligible/completed month cost plus event processing, subscription and policy costs. Acquisition charged once, fixed costs kept separate.
A14: Customer value | B14: Cohort block acquires one owner in month 1, no further acquisition, no CAC or fixed cost. Its discounted contribution is V36 before CAC; Summary subtracts CAC once.
... A24: Updated finite model | B24: Advanced Results, Inputs and Monthly contain labelled Python snapshots of the episodic model. Acquisition Curve has live nonlinear cost formulas. Run build_extension_examples.py before rebuilding advanced snapshots.

Sheet Parameters
A1: Illustrative assumptions — no empirical calibration
A2: q and payment are defined by the event basis. A renewal-rights switch is a hypothetical scenario, not a verified contract.
A4: Parameter | B4: Symbol | C4: Unit | D4: S1 | E4: S2 | F4: S3 | G4: S4 | H4: S5 | I4: S6 | J4: Definition / evidence
A5: Architecture selector | B5: z_N | C5: 0 lead; 1 bound policy | D5: 0 | E5: 0 | F5: 0 | G5: 0 | H5: 0 | I5: 1 | J5: Alternatives, not simultaneous initial remuneration; ILLUSTRATIVE
A6: Payable-event probability | B6: q | C6: fraction | D6: 0.1 | E6: 0.1 | F6: 0.1 | G6: 0.1 | H6: 0.1 | I6: 0.1 | J6: Lead acceptance or binding depending on selector; ILLUSTRATIVE
A7: Pre-event continuation | B7: rho_E | C7: fraction | D7: 0 | E7: 0 | F7: 0.8 | G7: 0.8 | H7: 0 | I7: 0 | J7: Unexhausted opportunity continuation; ILLUSTRATIVE
A8: Post-event continuation | B8: rho_M | C8: fraction | D8: 0 | E8: 0.8 | F8: 0.8 | G8: 0.8 | H8: 0.8 | I8: 0 | J8: Completed opportunity continuation; ILLUSTRATIVE
A9: New eligibility | B9: lambda | C9: fraction | D9: 0 | E9: 0 | F9: 0 | G9: 0.1 | H9: 0 | I9: 0 | J9: Genuine new payable episode; ILLUSTRATIVE
A10: Lead fee | B10: f_L | C10: EUR per lead | D10: 20 | E10: 20 | F10: 20 | G10: 20 | H10: 20 | I10: 20 | J10: Synthetic lead fee; ILLUSTRATIVE
A11: Eligible policy premium | B11: P | C11: EUR per policy | D11: 300 | E11: 300 | F11: 300 | G11: 300 | H11: 300 | I11: 300 | J11: Synthetic commission basis; ILLUSTRATIVE
A12: Initial commission rate | B12: nu_N | C12: fraction | D12: 0.1 | E12: 0.1 | F12: 0.1 | G12: 0.1 | H12: 0.1 | I12: 0.1 | J12: Synthetic rate; ILLUSTRATIVE
A13: Retained commission share | B13: s_N | C13: fraction | D13: 1 | E13: 1 | F13: 1 | G13: 1 | H13: 1 | I13: 1 | J13: Synthetic share; ILLUSTRATIVE
A14: Initial payment derived | B14: f | C14: EUR per event | D14: =IF(Parameters!$D$5=1,Parameters!$D$11*Parameters!$D$12*Parameters!$D$13,Parameters!$D$10) -> 20 | E14: =IF(Parameters!$E$5=1,Parameters!$E$11*Parameters!$E$12*Parameters!$E$13,Parameters!$E$10) -> 20 | F14: =IF(Parameters!$F$5=1,Parameters!$F$11*Parameters!$F$12*Parameters!$F$13,Parameters!$F$10) -> 20 | G14: =IF(Parameters!$G$5=1,Parameters!$G$11*Parameters!$G$12*Parameters!$G$13,Parameters!$G$10) -> 20 | H14: =IF(Parameters!$H$5=1,Parameters!$H$11*Parameters!$H$12*Parameters!$H$13,Parameters!$H$10) -> 20 | I14: =IF(Parameters!$I$5=1,Parameters!$I$11*Parameters!$I$12*Parameters!$I$13,Parameters!$I$10) -> 30 | J14: Lead fee OR premium × rate × share; ILLUSTRATIVE
A15: Payment reversal fraction | B15: omega | C15: fraction | D15: 0.05 | E15: 0.05 | F15: 0.05 | G15: 0.05 | H15: 0.05 | I15: 0 | J15: Expected current-period credit; not policy survival; ILLUSTRATIVE
A16: Processing cost per event | B16: h | C16: EUR per event | D16: 1 | E16: 1 | F16: 1 | G16: 1 | H16: 1 | I16: 1 | J16: Synthetic event processing cost; ILLUSTRATIVE
A17: Eligible-owner monthly cost | B17: v_E | C17: EUR per owner-month | D17: 0.2 | E17: 0.2 | F17: 0.2 | G17: 0.2 | H17: 0.2 | I17: 0.2 | J17: Synthetic cost before event; ILLUSTRATIVE
A18: Completed-owner monthly cost | B18: v_M | C18: EUR per owner-month | D18: 0.3 | E18: 0.3 | F18: 0.3 | G18: 0.3 | H18: 0.3 | I18: 0.3 | J18: Synthetic cost after event; ILLUSTRATIVE
A19: Acquisition cost | B19: k | C19: EUR per acquired owner | D19: 4 | E19: 4 | F19: 4 | G19: 4 | H19: 4 | I19: 4 | J19: Synthetic CAC; ILLUSTRATIVE
A20: New owners per month | B20: A_t | C20: owners | D20: 1000 | E20: 1000 | F20: 1000 | G20: 1000 | H20: 1000 | I20: 1000 | J20: Synthetic calendar inflow; ILLUSTRATIVE
A21: Fixed monthly cost | B21: F | C21: EUR per month | D21: 1000 | E21: 1000 | F21: 1000 | G21: 1000 | H21: 1000 | I21: 1000 | J21: Synthetic fixed operating expense; ILLUSTRATIVE
A22: New software paid conversion | B22: kappa | C22: fraction | D22: 0 | E22: 0 | F22: 0 | G22: 0 | H22: 0.05 | I22: 0 | J22: Synthetic paid conversion; ILLUSTRATIVE
A23: Software billed continuation | B23: eta | C23: fraction | D23: 0.95 | E23: 0.95 | F23: 0.95 | G23: 0.95 | H23: 0.95 | I23: 0.95 | J23: Independent billing-cohort marginal; ILLUSTRATIVE
A24: Software monthly payment | B24: b | C24: EUR per billed month | D24: 3 | E24: 3 | F24: 3 | G24: 3 | H24: 3 | I24: 3 | J24: Synthetic monthly price; ILLUSTRATIVE
A25: Software monthly cost | B25: v_S | C25: EUR per billed month | D25: 0.5 | E25: 0.5 | F25: 0.5 | G25: 0.5 | H25: 0.5 | I25: 0.5 | J25: Synthetic incremental cost; ILLUSTRATIVE
A26: Renewal remuneration switch | B26: z_pi | C26: 0 or 1 | D26: 0 | E26: 0 | F26: 0 | G26: 0 | H26: 0 | I26: 1 | J26: Hypothetical rights; requires policy architecture; ILLUSTRATIVE
... A32: Monthly discount rate | B32: i | C32: fraction | D32: 0.01 | E32: 0.01 | F32: 0.01 | G32: 0.01 | H32: 0.01 | I32: 0.01 | J32: Synthetic time-value convention; ILLUSTRATIVE

Sheet Summary
A1: Counterfactual model outputs — illustrative only
A2: V36 is per one acquired owner. Calendar totals use 1,000 new owners per month and separate fixed costs. EUR in all examples.
A4: Case | B4: Architecture | C4: V36 before CAC | D4: V36 minus CAC | E4: Revenue 36 months | F4: Contribution 36 months | G4: Operating result 36 months | H4: Cash surplus 36 months | I4: Closing receivables | J4: Break-even CAC V36 | K4: Structural input check
A5: S1 | B5: Illustrative one-visit lead sales | C5: =SUM(S1!Z45:Z80) -> 1.6 | D5: =C5-Parameters!$D$19 -> -2.4 | E5: =SUM(S1!M5:M40) -> 68400 | F5: =SUM(S1!P5:P40) -> -86400 | G5: =SUM(S1!R5:R40) -> -122400 | H5: =SUM(S1!U5:U40) -> -124300 | I5: =S1!T40 -> 1900 | J5: =C5 -> 1.6 | K5: =IF(AND(Parameters!$D$5=0,Parameters!$D$26=1),"INVALID RIGHTS COMBINATION","OK: assumptions only") -> OK: assumptions only
A6: S2 | B6: Retain after first lead only | C6: =SUM(S2!Z45:Z80) -> 1.485747 | D6: =C6-Parameters!$E$19 -> -2.514253 | E6: =SUM(S2!M5:M40) -> 68400 | F6: =SUM(S2!P5:P40) -> -90120.195 | G6: =SUM(S2!R5:R40) -> -126120.19 | H6: =SUM(S2!U5:U40) -> -128020.19 | I6: =S2!T40 -> 1900 | J6: =C6 -> 1.485747 | K6: =IF(AND(Parameters!$E$5=0,Parameters!$E$26=1),"INVALID RIGHTS COMBINATION","OK: assumptions only") -> OK: assumptions only
A7: S3 | B7: Retain before and after first lead | C7: =SUM(S3!Z45:Z80) -> 5.1746777 | D7: =C7-Parameters!$F$19 -> 1.1746777 | E7: =SUM(S3!M5:M40) -> 226836.86 | F7: =SUM(S3!P5:P40) -> 34834.915 | G7: =SUM(S3!R5:R40) -> -1165.0848 | H7: =SUM(S3!U5:U40) -> -7950.7495 | I7: =S3!T40 -> 6785.6647 | J7: =C7 -> 5.1746777 | K7: =IF(AND(Parameters!$F$5=0,Parameters!$F$26=1),"INVALID RIGHTS COMBINATION","OK: assumptions only") -> OK: assumptions only
A8: S4 | B8: New eligible opportunities | C8: =SUM(S4!Z45:Z80) -> 5.8769525 | D8: =C8-Parameters!$G$19 -> 1.8769525 | E8: =SUM(S4!M5:M40) -> 247345.08 | F8: =SUM(S4!P5:P40) -> 55343.129 | G8: =SUM(S4!R5:R40) -> 19343.129 | H8: =SUM(S4!U5:U40) -> 11787.934 | I8: =S4!T40 -> 7555.1952 | J8: =C8 -> 5.8769525 | K8: =IF(AND(Parameters!$G$5=0,Parameters!$G$26=1),"INVALID RIGHTS COMBINATION","OK: assumptions only") -> OK: assumptions only
A9: S5 | B9: Paid tools with post-lead retention | C9: =SUM(S5!Z45:Z80) -> 3.357875 | D9: =C9-Parameters!$H$19 -> -0.64212505 | E9: =SUM(S5!M5:M40) -> 128393.42 | F9: =SUM(S5!P5:P40) -> -40125.682 | G9: =SUM(S5!R5:R40) -> -76125.682 | H9: =SUM(S5!U5:U40) -> -80552.344 | I9: =S5!T40 -> 4426.6624 | J9: =C9 -> 3.357875 | K9: =IF(AND(Parameters!$H$5=0,Parameters!$H$26=1),"INVALID RIGHTS COMBINATION","OK: assumptions only") -> OK: assumptions only
A10: S6 | B10: Policy commission and renewal hypothesis | C10: =SUM(S6!Z45:Z80) -> 4.2490816 | D10: =C10-Parameters!$I$19 -> 0.24908164 | E10: =SUM(S6!M5:M40) -> 147333.85 | F10: =SUM(S6!P5:P40) -> -12804.874 | G10: =SUM(S6!R5:R40) -> -48804.874 | H10: =SUM(S6!U5:U40) -> -53905.619 | I10: =S6!T40 -> 5100.7456 | J10: =C10 -> 4.2490816 | K10: =IF(AND(Parameters!$I$5=0,Parameters!$I$26=1),"INVALID RIGHTS COMBINATION","OK: assumptions only") -> OK: assumptions only

Sheet S1
A1: S1 — Illustrative one-visit lead sales
A2: All parameters are illustrative. Top block: calendar cohorts. Lower block: one acquired owner, no CAC/fixed cost, for customer-value calculation.
A4: Month | B4: Acquired | C4: E eligible | D4: M completed active | E4: Payable events | F4: New policies | G4: Active policies | H4: Renewed policies | I4: Billed subscribers | J4: Initial revenue | K4: Renewal revenue | L4: Software revenue | M4: Total revenue | N4: Variable cost | O4: Acquisition cost | P4: Contribution | Q4: Fixed cost | R4: Operating result | S4: Cash receipts | T4: Receivables | U4: Cash surplus | V4: Cumulative cash | W4: Churned opportunity owners | X4: Next E | Y4: Next M | Z4: Discounted contribution before CAC
A5: 1 | B5: =Parameters!$D$20 -> 1000 | C5: =B5 -> 1000 | D5: =0 -> 0 | E5: =Parameters!$D$6*C5 -> 100 | F5: =IF(Parameters!$D$5=1,E5,0) -> 0 | G5: =F5 -> 0 | H5: =IF(AND(Parameters!$D$5=1,Parameters!$D$26=1),SUMPRODUCT(--($A$5:A5<A5),--(MOD(A5-$A$5:A5,Parameters!$D$28)=0),$F$5:F5,POWER(Parameters!$D$27,IF(A5-$A$5:A5=0,1,A5-$A$5:A5))),0) -> 0 | I5: =B5*Parameters!$D$22 -> 0 | J5: =E5*Parameters!$D$14*(1-Parameters!$D$15) -> 1900 | K5: =H5*Parameters!$D$29 -> 0 | L5: =I5*Parameters!$D$24 -> 0 | M5: =J5+K5+L5 -> 1900 | N5: =C5*Parameters!$D$17+D5*Parameters!$D$18+E5*Parameters!$D$16+I5*Parameters!$D$25+G5*Parameters!$D$30 -> 300 | O5: =B5*Parameters!$D$19 -> 4000 | P5: =M5-N5-O5 -> -2400 | Q5: =Parameters!$D$21 -> 1000 | R5: =P5-Q5 -> -3400 | S5: =IF(A5<1+Parameters!$D$31,0,INDEX($M$5:$M$40,A5-Parameters!$D$31)) -> 0 | T5: =M5-S5 -> 1900 | U5: =S5-N5-O5-Q5 -> -5300 | V5: =U5 -> -5300 | W5: =(1-Parameters!$D$7)*(C5-E5)+(1-Parameters!$D$8)*(D5+E5) -> 1000 | X5: =Parameters!$D$7*(C5-E5)+Parameters!$D$8*Parameters!$D$9*(D5+E5) -> 0 | Y5: =Parameters!$D$8*(1-Parameters!$D$9)*(D5+E5) -> 0 | Z5: =POWER(1/(1+Parameters!$D$32),A5-1)*(M5-N5) -> 1600
A6: 2 | B6: =Parameters!$D$20 -> 1000 | C6: =X5+B6 -> 1000 | D6: =Y5 -> 0 | E6: =Parameters!$D$6*C6 -> 100 | F6: =IF(Parameters!$D$5=1,E6,0) -> 0 | G6: =Parameters!$D$27*G5+F6 -> 0 | H6: =IF(AND(Parameters!$D$5=1,Parameters!$D$26=1),SUMPRODUCT(--($A$5:A6<A6),--(MOD(A6-$A$5:A6,Parameters!$D$28)=0),$F$5:F6,POWER(Parameters!$D$27,IF(A6-$A$5:A6=0,1,A6-$A$5:A6))),0) -> 0 | I6: =Parameters!$D$23*I5+B6*Parameters!$D$22 -> 0 | J6: =E6*Parameters!$D$14*(1-Parameters!$D$15) -> 1900 | K6: =H6*Parameters!$D$29 -> 0 | L6: =I6*Parameters!$D$24 -> 0 | M6: =J6+K6+L6 -> 1900 | N6: =C6*Parameters!$D$17+D6*Parameters!$D$18+E6*Parameters!$D$16+I6*Parameters!$D$25+G6*Parameters!$D$30 -> 300 | O6: =B6*Parameters!$D$19 -> 4000 | P6: =M6-N6-O6 -> -2400 | Q6: =Parameters!$D$21 -> 1000 | R6: =P6-Q6 -> -3400 | S6: =IF(A6<1+Parameters!$D$31,0,INDEX($M$5:$M$40,A6-Parameters!$D$31)) -> 1900 | T6: =T5+M6-S6 -> 1900 | U6: =S6-N6-O6-Q6 -> -3400 | V6: =V5+U6 -> -8700 | W6: =(1-Parameters!$D$7)*(C6-E6)+(1-Parameters!$D$8)*(D6+E6) -> 1000 | X6: =Parameters!$D$7*(C6-E6)+Parameters!$D$8*Parameters!$D$9*(D6+E6) -> 0 | Y6: =Parameters!$D$8*(1-Parameters!$D$9)*(D6+E6) -> 0 | Z6: =POWER(1/(1+Parameters!$D$32),A6-1)*(M6-N6) -> 1584.1584
A7: 3 | B7: =Parameters!$D$20 -> 1000 | C7: =X6+B7 -> 1000 | D7: =Y6 -> 0 | E7: =Parameters!$D$6*C7 -> 100 | F7: =IF(Parameters!$D$5=1,E7,0) -> 0 | G7: =Parameters!$D$27*G6+F7 -> 0 | H7: =IF(AND(Parameters!$D$5=1,Parameters!$D$26=1),SUMPRODUCT(--($A$5:A7<A7),--(MOD(A7-$A$5:A7,Parameters!$D$28)=0),$F$5:F7,POWER(Parameters!$D$27,IF(A7-$A$5:A7=0,1,A7-$A$5:A7))),0) -> 0 | I7: =Parameters!$D$23*I6+B7*Parameters!$D$22 -> 0 | J7: =E7*Parameters!$D$14*(1-Parameters!$D$15) -> 1900 | K7: =H7*Parameters!$D$29 -> 0 | L7: =I7*Parameters!$D$24 -> 0 | M7: =J7+K7+L7 -> 1900 | N7: =C7*Parameters!$D$17+D7*Parameters!$D$18+E7*Parameters!$D$16+I7*Parameters!$D$25+G7*Parameters!$D$30 -> 300 | O7: =B7*Parameters!$D$19 -> 4000 | P7: =M7-N7-O7 -> -2400 | Q7: =Parameters!$D$21 -> 1000 | R7: =P7-Q7 -> -3400 | S7: =IF(A7<1+Parameters!$D$31,0,INDEX($M$5:$M$40,A7-Parameters!$D$31)) -> 1900 | T7: =T6+M7-S7 -> 1900 | U7: =S7-N7-O7-Q7 -> -3400 | V7: =V6+U7 -> -12100 | W7: =(1-Parameters!$D$7)*(C7-E7)+(1-Parameters!$D$8)*(D7+E7) -> 1000 | X7: =Parameters!$D$7*(C7-E7)+Parameters!$D$8*Parameters!$D$9*(D7+E7) -> 0 | Y7: =Parameters!$D$8*(1-Parameters!$D$9)*(D7+E7) -> 0 | Z7: =POWER(1/(1+Parameters!$D$32),A7-1)*(M7-N7) -> 1568.4737
A8: 4 | B8: =Parameters!$D$20 -> 1000 | C8: =X7+B8 -> 1000 | D8: =Y7 -> 0 | E8: =Parameters!$D$6*C8 -> 100 | F8: =IF(Parameters!$D$5=1,E8,0) -> 0 | G8: =Parameters!$D$27*G7+F8 -> 0 | H8: =IF(AND(Parameters!$D$5=1,Parameters!$D$26=1),SUMPRODUCT(--($A$5:A8<A8),--(MOD(A8-$A$5:A8,Parameters!$D$28)=0),$F$5:F8,POWER(Parameters!$D$27,IF(A8-$A$5:A8=0,1,A8-$A$5:A8))),0) -> 0 | I8: =Parameters!$D$23*I7+B8*Parameters!$D$22 -> 0 | J8: =E8*Parameters!$D$14*(1-Parameters!$D$15) -> 1900 | K8: =H8*Parameters!$D$29 -> 0 | L8: =I8*Parameters!$D$24 -> 0 | M8: =J8+K8+L8 -> 1900 | N8: =C8*Parameters!$D$17+D8*Parameters!$D$18+E8*Parameters!$D$16+I8*Parameters!$D$25+G8*Parameters!$D$30 -> 300 | O8: =B8*Parameters!$D$19 -> 4000 | P8: =M8-N8-O8 -> -2400 | Q8: =Parameters!$D$21 -> 1000 | R8: =P8-Q8 -> -3400 | S8: =IF(A8<1+Parameters!$D$31,0,INDEX($M$5:$M$40,A8-Parameters!$D$31)) -> 1900 | T8: =T7+M8-S8 -> 1900 | U8: =S8-N8-O8-Q8 -> -3400 | V8: =V7+U8 -> -15500 | W8: =(1-Parameters!$D$7)*(C8-E8)+(1-Parameters!$D$8)*(D8+E8) -> 1000 | X8: =Parameters!$D$7*(C8-E8)+Parameters!$D$8*Parameters!$D$9*(D8+E8) -> 0 | Y8: =Parameters!$D$8*(1-Parameters!$D$9)*(D8+E8) -> 0 | Z8: =POWER(1/(1+Parameters!$D$32),A8-1)*(M8-N8) -> 1552.9442
A9: 5 | B9: =Parameters!$D$20 -> 1000 | C9: =X8+B9 -> 1000 | D9: =Y8 -> 0 | E9: =Parameters!$D$6*C9 -> 100 | F9: =IF(Parameters!$D$5=1,E9,0) -> 0 | G9: =Parameters!$D$27*G8+F9 -> 0 | H9: =IF(AND(Parameters!$D$5=1,Parameters!$D$26=1),SUMPRODUCT(--($A$5:A9<A9),--(MOD(A9-$A$5:A9,Parameters!$D$28)=0),$F$5:F9,POWER(Parameters!$D$27,IF(A9-$A$5:A9=0,1,A9-$A$5:A9))),0) -> 0 | I9: =Parameters!$D$23*I8+B9*Parameters!$D$22 -> 0 | J9: =E9*Parameters!$D$14*(1-Parameters!$D$15) -> 1900 | K9: =H9*Parameters!$D$29 -> 0 | L9: =I9*Parameters!$D$24 -> 0 | M9: =J9+K9+L9 -> 1900 | N9: =C9*Parameters!$D$17+D9*Parameters!$D$18+E9*Parameters!$D$16+I9*Parameters!$D$25+G9*Parameters!$D$30 -> 300 | O9: =B9*Parameters!$D$19 -> 4000 | P9: =M9-N9-O9 -> -2400 | Q9: =Parameters!$D$21 -> 1000 | R9: =P9-Q9 -> -3400 | S9: =IF(A9<1+Parameters!$D$31,0,INDEX($M$5:$M$40,A9-Parameters!$D$31)) -> 1900 | T9: =T8+M9-S9 -> 1900 | U9: =S9-N9-O9-Q9 -> -3400 | V9: =V8+U9 -> -18900 | W9: =(1-Parameters!$D$7)*(C9-E9)+(1-Parameters!$D$8)*(D9+E9) -> 1000 | X9: =Parameters!$D$7*(C9-E9)+Parameters!$D$8*Parameters!$D$9*(D9+E9) -> 0 | Y9: =Parameters!$D$8*(1-Parameters!$D$9)*(D9+E9) -> 0 | Z9: =POWER(1/(1+Parameters!$D$32),A9-1)*(M9-N9) -> 1537.5686
A10: 6 | B10: =Parameters!$D$20 -> 1000 | C10: =X9+B10 -> 1000 | D10: =Y9 -> 0 | E10: =Parameters!$D$6*C10 -> 100 | F10: =IF(Parameters!$D$5=1,E10,0) -> 0 | G10: =Parameters!$D$27*G9+F10 -> 0 | H10: =IF(AND(Parameters!$D$5=1,Parameters!$D$26=1),SUMPRODUCT(--($A$5:A10<A10),--(MOD(A10-$A$5:A10,Parameters!$D$28)=0),$F$5:F10,POWER(Parameters!$D$27,IF(A10-$A$5:A10=0,1,A10-$A$5:A10))),0) -> 0 | I10: =Parameters!$D$23*I9+B10*Parameters!$D$22 -> 0 | J10: =E10*Parameters!$D$14*(1-Parameters!$D$15) -> 1900 | K10: =H10*Parameters!$D$29 -> 0 | L10: =I10*Parameters!$D$24 -> 0 | M10: =J10+K10+L10 -> 1900 | N10: =C10*Parameters!$D$17+D10*Parameters!$D$18+E10*Parameters!$D$16+I10*Parameters!$D$25+G10*Parameters!$D$30 -> 300 | O10: =B10*Parameters!$D$19 -> 4000 | P10: =M10-N10-O10 -> -2400 | Q10: =Parameters!$D$21 -> 1000 | R10: =P10-Q10 -> -3400 | S10: =IF(A10<1+Parameters!$D$31,0,INDEX($M$5:$M$40,A10-Parameters!$D$31)) -> 1900 | T10: =T9+M10-S10 -> 1900 | U10: =S10-N10-O10-Q10 -> -3400 | V10: =V9+U10 -> -22300 | W10: =(1-Parameters!$D$7)*(C10-E10)+(1-Parameters!$D$8)*(D10+E10) -> 1000 | X10: =Parameters!$D$7*(C10-E10)+Parameters!$D$8*Parameters!$D$9*(D10+E10) -> 0 | Y10: =Parameters!$D$8*(1-Parameters!$D$9)*(D10+E10) -> 0 | Z10: =POWER(1/(1+Parameters!$D$32),A10-1)*(M10-N10) -> 1522.3451
A11: 7 | B11: =Parameters!$D$20 -> 1000 | C11: =X10+B11 -> 1000 | D11: =Y10 -> 0 | E11: =Parameters!$D$6*C11 -> 100 | F11: =IF(Parameters!$D$5=1,E11,0) -> 0 | G11: =Parameters!$D$27*G10+F11 -> 0 | H11: =IF(AND(Parameters!$D$5=1,Parameters!$D$26=1),SUMPRODUCT(--($A$5:A11<A11),--(MOD(A11-$A$5:A11,Parameters!$D$28)=0),$F$5:F11,POWER(Parameters!$D$27,IF(A11-$A$5:A11=0,1,A11-$A$5:A11))),0) -> 0 | I11: =Parameters!$D$23*I10+B11*Parameters!$D$22 -> 0 | J11: =E11*Parameters!$D$14*(1-Parameters!$D$15) -> 1900 | K11: =H11*Parameters!$D$29 -> 0 | L11: =I11*Parameters!$D$24 -> 0 | M11: =J11+K11+L11 -> 1900 | N11: =C11*Parameters!$D$17+D11*Parameters!$D$18+E11*Parameters!$D$16+I11*Parameters!$D$25+G11*Parameters!$D$30 -> 300 | O11: =B11*Parameters!$D$19 -> 4000 | P11: =M11-N11-O11 -> -2400 | Q11: =Parameters!$D$21 -> 1000 | R11: =P11-Q11 -> -3400 | S11: =IF(A11<1+Parameters!$D$31,0,INDEX($M$5:$M$40,A11-Parameters!$D$31)) -> 1900 | T11: =T10+M11-S11 -> 1900 | U11: =S11-N11-O11-Q11 -> -3400 | V11: =V10+U11 -> -25700 | W11: =(1-Parameters!$D$7)*(C11-E11)+(1-Parameters!$D$8)*(D11+E11) -> 1000 | X11: =Parameters!$D$7*(C11-E11)+Parameters!$D$8*Parameters!$D$9*(D11+E11) -> 0 | Y11: =Parameters!$D$8*(1-Parameters!$D$9)*(D11+E11) -> 0 | Z11: =POWER(1/(1+Parameters!$D$32),A11-1)*(M11-N11) -> 1507.2724
A12: 8 | B12: =Parameters!$D$20 -> 1000 | C12: =X11+B12 -> 1000 | D12: =Y11 -> 0 | E12: =Parameters!$D$6*C12 -> 100 | F12: =IF(Parameters!$D$5=1,E12,0) -> 0 | G12: =Parameters!$D$27*G11+F12 -> 0 | H12: =IF(AND(Parameters!$D$5=1,Parameters!$D$26=1),SUMPRODUCT(--($A$5:A12<A12),--(MOD(A12-$A$5:A12,Parameters!$D$28)=0),$F$5:F12,POWER(Parameters!$D$27,IF(A12-$A$5:A12=0,1,A12-$A$5:A12))),0) -> 0 | I12: =Parameters!$D$23*I11+B12*Parameters!$D$22 -> 0 | J12: =E12*Parameters!$D$14*(1-Parameters!$D$15) -> 1900 | K12: =H12*Parameters!$D$29 -> 0 | L12: =I12*Parameters!$D$24 -> 0 | M12: =J12+K12+L12 -> 1900 | N12: =C12*Parameters!$D$17+D12*Parameters!$D$18+E12*Parameters!$D$16+I12*Parameters!$D$25+G12*Parameters!$D$30 -> 300 | O12: =B12*Parameters!$D$19 -> 4000 | P12: =M12-N12-O12 -> -2400 | Q12: =Parameters!$D$21 -> 1000 | R12: =P12-Q12 -> -3400 | S12: =IF(A12<1+Parameters!$D$31,0,INDEX($M$5:$M$40,A12-Parameters!$D$31)) -> 1900 | T12: =T11+M12-S12 -> 1900 | U12: =S12-N12-O12-Q12 -> -3400 | V12: =V11+U12 -> -29100 | W12: =(1-Parameters!$D$7)*(C12-E12)+(1-Parameters!$D$8)*(D12+E12) -> 1000 | X12: =Parameters!$D$7*(C12-E12)+Parameters!$D$8*Parameters!$D$9*(D12+E12) -> 0 | Y12: =Parameters!$D$8*(1-Parameters!$D$9)*(D12+E12) -> 0 | Z12: =POWER(1/(1+Parameters!$D$32),A12-1)*(M12-N12) -> 1492.3489
A13: 9 | B13: =Parameters!$D$20 -> 1000 | C13: =X12+B13 -> 1000 | D13: =Y12 -> 0 | E13: =Parameters!$D$6*C13 -> 100 | F13: =IF(Parameters!$D$5=1,E13,0) -> 0 | G13: =Parameters!$D$27*G12+F13 -> 0 | H13: =IF(AND(Parameters!$D$5=1,Parameters!$D$26=1),SUMPRODUCT(--($A$5:A13<A13),--(MOD(A13-$A$5:A13,Parameters!$D$28)=0),$F$5:F13,POWER(Parameters!$D$27,IF(A13-$A$5:A13=0,1,A13-$A$5:A13))),0) -> 0 | I13: =Parameters!$D$23*I12+B13*Parameters!$D$22 -> 0 | J13: =E13*Parameters!$D$14*(1-Parameters!$D$15) -> 1900 | K13: =H13*Parameters!$D$29 -> 0 | L13: =I13*Parameters!$D$24 -> 0 | M13: =J13+K13+L13 -> 1900 | N13: =C13*Parameters!$D$17+D13*Parameters!$D$18+E13*Parameters!$D$16+I13*Parameters!$D$25+G13*Parameters!$D$30 -> 300 | O13: =B13*Parameters!$D$19 -> 4000 | P13: =M13-N13-O13 -> -2400 | Q13: =Parameters!$D$21 -> 1000 | R13: =P13-Q13 -> -3400 | S13: =IF(A13<1+Parameters!$D$31,0,INDEX($M$5:$M$40,A13-Parameters!$D$31)) -> 1900 | T13: =T12+M13-S13 -> 1900 | U13: =S13-N13-O13-Q13 -> -3400 | V13: =V12+U13 -> -32500 | W13: =(1-Parameters!$D$7)*(C13-E13)+(1-Parameters!$D$8)*(D13+E13) -> 1000 | X13: =Parameters!$D$7*(C13-E13)+Parameters!$D$8*Parameters!$D$9*(D13+E13) -> 0 | Y13: =Parameters!$D$8*(1-Parameters!$D$9)*(D13+E13) -> 0 | Z13: =POWER(1/(1+Parameters!$D$32),A13-1)*(M13-N13) -> 1477.5732
A14: 10 | B14: =Parameters!$D$20 -> 1000 | C14: =X13+B14 -> 1000 | D14: =Y13 -> 0 | E14: =Parameters!$D$6*C14 -> 100 | F14: =IF(Parameters!$D$5=1,E14,0) -> 0 | G14: =Parameters!$D$27*G13+F14 -> 0 | H14: =IF(AND(Parameters!$D$5=1,Parameters!$D$26=1),SUMPRODUCT(--($A$5:A14<A14),--(MOD(A14-$A$5:A14,Parameters!$D$28)=0),$F$5:F14,POWER(Parameters!$D$27,IF(A14-$A$5:A14=0,1,A14-$A$5:A14))),0) -> 0 | I14: =Parameters!$D$23*I13+B14*Parameters!$D$22 -> 0 | J14: =E14*Parameters!$D$14*(1-Parameters!$D$15) -> 1900 | K14: =H14*Parameters!$D$29 -> 0 | L14: =I14*Parameters!$D$24 -> 0 | M14: =J14+K14+L14 -> 1900 | N14: =C14*Parameters!$D$17+D14*Parameters!$D$18+E14*Parameters!$D$16+I14*Parameters!$D$25+G14*Parameters!$D$30 -> 300 | O14: =B14*Parameters!$D$19 -> 4000 | P14: =M14-N14-O14 -> -2400 | Q14: =Parameters!$D$21 -> 1000 | R14: =P14-Q14 -> -3400 | S14: =IF(A14<1+Parameters!$D$31,0,INDEX($M$5:$M$40,A14-Parameters!$D$31)) -> 1900 | T14: =T13+M14-S14 -> 1900 | U14: =S14-N14-O14-Q14 -> -3400 | V14: =V13+U14 -> -35900 | W14: =(1-Parameters!$D$7)*(C14-E14)+(1-Parameters!$D$8)*(D14+E14) -> 1000 | X14: =Parameters!$D$7*(C14-E14)+Parameters!$D$8*Parameters!$D$9*(D14+E14) -> 0 | Y14: =Parameters!$D$8*(1-Parameters!$D$9)*(D14+E14) -> 0 | Z14: =POWER(1/(1+Parameters!$D$32),A14-1)*(M14-N14) -> 1462.9437
A15: 11 | B15: =Parameters!$D$20 -> 1000 | C15: =X14+B15 -> 1000 | D15: =Y14 -> 0 | E15: =Parameters!$D$6*C15 -> 100 | F15: =IF(Parameters!$D$5=1,E15,0) -> 0 | G15: =Parameters!$D$27*G14+F15 -> 0 | H15: =IF(AND(Parameters!$D$5=1,Parameters!$D$26=1),SUMPRODUCT(--($A$5:A15<A15),--(MOD(A15-$A$5:A15,Parameters!$D$28)=0),$F$5:F15,POWER(Parameters!$D$27,IF(A15-$A$5:A15=0,1,A15-$A$5:A15))),0) -> 0 | I15: =Parameters!$D$23*I14+B15*Parameters!$D$22 -> 0 | J15: =E15*Parameters!$D$14*(1-Parameters!$D$15) -> 1900 | K15: =H15*Parameters!$D$29 -> 0 | L15: =I15*Parameters!$D$24 -> 0 | M15: =J15+K15+L15 -> 1900 | N15: =C15*Parameters!$D$17+D15*Parameters!$D$18+E15*Parameters!$D$16+I15*Parameters!$D$25+G15*Parameters!$D$30 -> 300 | O15: =B15*Parameters!$D$19 -> 4000 | P15: =M15-N15-O15 -> -2400 | Q15: =Parameters!$D$21 -> 1000 | R15: =P15-Q15 -> -3400 | S15: =IF(A15<1+Parameters!$D$31,0,INDEX($M$5:$M$40,A15-Parameters!$D$31)) -> 1900 | T15: =T14+M15-S15 -> 1900 | U15: =S15-N15-O15-Q15 -> -3400 | V15: =V14+U15 -> -39300 | W15: =(1-Parameters!$D$7)*(C15-E15)+(1-Parameters!$D$8)*(D15+E15) -> 1000 | X15: =Parameters!$D$7*(C15-E15)+Parameters!$D$8*Parameters!$D$9*(D15+E15) -> 0 | Y15: =Parameters!$D$8*(1-Parameters!$D$9)*(D15+E15) -> 0 | Z15: =POWER(1/(1+Parameters!$D$32),A15-1)*(M15-N15) -> 1448.4591
A16: 12 | B16: =Parameters!$D$20 -> 1000 | C16: =X15+B16 -> 1000 | D16: =Y15 -> 0 | E16: =Parameters!$D$6*C16 -> 100 | F16: =IF(Parameters!$D$5=1,E16,0) -> 0 | G16: =Parameters!$D$27*G15+F16 -> 0 | H16: =IF(AND(Parameters!$D$5=1,Parameters!$D$26=1),SUMPRODUCT(--($A$5:A16<A16),--(MOD(A16-$A$5:A16,Parameters!$D$28)=0),$F$5:F16,POWER(Parameters!$D$27,IF(A16-$A$5:A16=0,1,A16-$A$5:A16))),0) -> 0 | I16: =Parameters!$D$23*I15+B16*Parameters!$D$22 -> 0 | J16: =E16*Parameters!$D$14*(1-Parameters!$D$15) -> 1900 | K16: =H16*Parameters!$D$29 -> 0 | L16: =I16*Parameters!$D$24 -> 0 | M16: =J16+K16+L16 -> 1900 | N16: =C16*Parameters!$D$17+D16*Parameters!$D$18+E16*Parameters!$D$16+I16*Parameters!$D$25+G16*Parameters!$D$30 -> 300 | O16: =B16*Parameters!$D$19 -> 4000 | P16: =M16-N16-O16 -> -2400 | Q16: =Parameters!$D$21 -> 1000 | R16: =P16-Q16 -> -3400 | S16: =IF(A16<1+Parameters!$D$31,0,INDEX($M$5:$M$40,A16-Parameters!$D$31)) -> 1900 | T16: =T15+M16-S16 -> 1900 | U16: =S16-N16-O16-Q16 -> -3400 | V16: =V15+U16 -> -42700 | W16: =(1-Parameters!$D$7)*(C16-E16)+(1-Parameters!$D$8)*(D16+E16) -> 1000 | X16: =Parameters!$D$7*(C16-E16)+Parameters!$D$8*Parameters!$D$9*(D16+E16) -> 0 | Y16: =Parameters!$D$8*(1-Parameters!$D$9)*(D16+E16) -> 0 | Z16: =POWER(1/(1+Parameters!$D$32),A16-1)*(M16-N16) -> 1434.1179
A17: 13 | B17: =Parameters!$D$20 -> 1000 | C17: =X16+B17 -> 1000 | D17: =Y16 -> 0 | E17: =Parameters!$D$6*C17 -> 100 | F17: =IF(Parameters!$D$5=1,E17,0) -> 0 | G17: =Parameters!$D$27*G16+F17 -> 0 | H17: =IF(AND(Parameters!$D$5=1,Parameters!$D$26=1),SUMPRODUCT(--($A$5:A17<A17),--(MOD(A17-$A$5:A17,Parameters!$D$28)=0),$F$5:F17,POWER(Parameters!$D$27,IF(A17-$A$5:A17=0,1,A17-$A$5:A17))),0) -> 0 | I17: =Parameters!$D$23*I16+B17*Parameters!$D$22 -> 0 | J17: =E17*Parameters!$D$14*(1-Parameters!$D$15) -> 1900 | K17: =H17*Parameters!$D$29 -> 0 | L17: =I17*Parameters!$D$24 -> 0 | M17: =J17+K17+L17 -> 1900 | N17: =C17*Parameters!$D$17+D17*Parameters!$D$18+E17*Parameters!$D$16+I17*Parameters!$D$25+G17*Parameters!$D$30 -> 300 | O17: =B17*Parameters!$D$19 -> 4000 | P17: =M17-N17-O17 -> -2400 | Q17: =Parameters!$D$21 -> 1000 | R17: =P17-Q17 -> -3400 | S17: =IF(A17<1+Parameters!$D$31,0,INDEX($M$5:$M$40,A17-Parameters!$D$31)) -> 1900 | T17: =T16+M17-S17 -> 1900 | U17: =S17-N17-O17-Q17 -> -3400 | V17: =V16+U17 -> -46100 | W17: =(1-Parameters!$D$7)*(C17-E17)+(1-Parameters!$D$8)*(D17+E17) -> 1000 | X17: =Parameters!$D$7*(C17-E17)+Parameters!$D$8*Parameters!$D$9*(D17+E17) -> 0 | Y17: =Parameters!$D$8*(1-Parameters!$D$9)*(D17+E17) -> 0 | Z17: =POWER(1/(1+Parameters!$D$32),A17-1)*(M17-N17) -> 1419.9188
... A40: 36 | B40: =Parameters!$D$20 -> 1000 | C40: =X39+B40 -> 1000 | D40: =Y39 -> 0 | E40: =Parameters!$D$6*C40 -> 100 | F40: =IF(Parameters!$D$5=1,E40,0) -> 0 | G40: =Parameters!$D$27*G39+F40 -> 0 | H40: =IF(AND(Parameters!$D$5=1,Parameters!$D$26=1),SUMPRODUCT(--($A$5:A40<A40),--(MOD(A40-$A$5:A40,Parameters!$D$28)=0),$F$5:F40,POWER(Parameters!$D$27,IF(A40-$A$5:A40=0,1,A40-$A$5:A40))),0) -> 0 | I40: =Parameters!$D$23*I39+B40*Parameters!$D$22 -> 0 | J40: =E40*Parameters!$D$14*(1-Parameters!$D$15) -> 1900 | K40: =H40*Parameters!$D$29 -> 0 | L40: =I40*Parameters!$D$24 -> 0 | M40: =J40+K40+L40 -> 1900 | N40: =C40*Parameters!$D$17+D40*Parameters!$D$18+E40*Parameters!$D$16+I40*Parameters!$D$25+G40*Parameters!$D$30 -> 300 | O40: =B40*Parameters!$D$19 -> 4000 | P40: =M40-N40-O40 -> -2400 | Q40: =Parameters!$D$21 -> 1000 | R40: =P40-Q40 -> -3400 | S40: =IF(A40<1+Parameters!$D$31,0,INDEX($M$5:$M$40,A40-Parameters!$D$31)) -> 1900 | T40: =T39+M40-S40 -> 1900 | U40: =S40-N40-O40-Q40 -> -3400 | V40: =V39+U40 -> -124300 | W40: =(1-Parameters!$D$7)*(C40-E40)+(1-Parameters!$D$8)*(D40+E40) -> 1000 | X40: =Parameters!$D$7*(C40-E40)+Parameters!$D$8*Parameters!$D$9*(D40+E40) -> 0 | Y40: =Parameters!$D$8*(1-Parameters!$D$9)*(D40+E40) -> 0 | Z40: =POWER(1/(1+Parameters!$D$32),A40-1)*(M40-N40) -> 1129.4627
A43: One acquired-owner cohort: V36 before acquisition/fixed costs. This isolates the mathematical unit value.
A44: Month | B44: Acquired | C44: E eligible | D44: M completed active | E44: Payable events | F44: New policies | G44: Active policies | H44: Renewed policies | I44: Billed subscribers | J44: Initial revenue | K44: Renewal revenue | L44: Software revenue | M44: Total revenue | N44: Variable cost | O44: Acquisition cost | P44: Contribution | Q44: Fixed cost | R44: Operating result | S44: Cash receipts | T44: Receivables | U44: Cash surplus | V44: Cumulative cash | W44: Churned opportunity owners | X44: Next E | Y44: Next M | Z44: Discounted contribution before CAC
A45: 1 | B45: =1 -> 1 | C45: =B45 -> 1 | D45: =0 -> 0 | E45: =Parameters!$D$6*C45 -> 0.1 | F45: =IF(Parameters!$D$5=1,E45,0) -> 0 | G45: =F45 -> 0 | H45: =IF(AND(Parameters!$D$5=1,Parameters!$D$26=1),SUMPRODUCT(--($A$45:A45<A45),--(MOD(A45-$A$45:A45,Parameters!$D$28)=0),$F$45:F45,POWER(Parameters!$D$27,IF(A45-$A$45:A45=0,1,A45-$A$45:A45))),0) -> 0 | I45: =B45*Parameters!$D$22 -> 0 | J45: =E45*Parameters!$D$14*(1-Parameters!$D$15) -> 1.9 | K45: =H45*Parameters!$D$29 -> 0 | L45: =I45*Parameters!$D$24 -> 0 | M45: =J45+K45+L45 -> 1.9 | N45: =C45*Parameters!$D$17+D45*Parameters!$D$18+E45*Parameters!$D$16+I45*Parameters!$D$25+G45*Parameters!$D$30 -> 0.3 | O45: =0 -> 0 | P45: =M45-N45-O45 -> 1.6 | Q45: =0 -> 0 | R45: =P45-Q45 -> 1.6 | S45: =IF(A45<1+Parameters!$D$31,0,INDEX($M$45:$M$80,A45-Parameters!$D$31)) -> 0 | T45: =M45-S45 -> 1.9 | U45: =S45-N45-O45-Q45 -> -0.3 | V45: =U45 -> -0.3 | W45: =(1-Parameters!$D$7)*(C45-E45)+(1-Parameters!$D$8)*(D45+E45) -> 1 | X45: =Parameters!$D$7*(C45-E45)+Parameters!$D$8*Parameters!$D$9*(D45+E45) -> 0 | Y45: =Parameters!$D$8*(1-Parameters!$D$9)*(D45+E45) -> 0 | Z45: =POWER(1/(1+Parameters!$D$32),A45-1)*(M45-N45) -> 1.6
A46: 2 | B46: =0 -> 0 | C46: =X45+B46 -> 0 | D46: =Y45 -> 0 | E46: =Parameters!$D$6*C46 -> 0 | F46: =IF(Parameters!$D$5=1,E46,0) -> 0 | G46: =Parameters!$D$27*G45+F46 -> 0 | H46: =IF(AND(Parameters!$D$5=1,Parameters!$D$26=1),SUMPRODUCT(--($A$45:A46<A46),--(MOD(A46-$A$45:A46,Parameters!$D$28)=0),$F$45:F46,POWER(Parameters!$D$27,IF(A46-$A$45:A46=0,1,A46-$A$45:A46))),0) -> 0 | I46: =Parameters!$D$23*I45+B46*Parameters!$D$22 -> 0 | J46: =E46*Parameters!$D$14*(1-Parameters!$D$15) -> 0 | K46: =H46*Parameters!$D$29 -> 0 | L46: =I46*Parameters!$D$24 -> 0 | M46: =J46+K46+L46 -> 0 | N46: =C46*Parameters!$D$17+D46*Parameters!$D$18+E46*Parameters!$D$16+I46*Parameters!$D$25+G46*Parameters!$D$30 -> 0 | O46: =0 -> 0 | P46: =M46-N46-O46 -> 0 | Q46: =0 -> 0 | R46: =P46-Q46 -> 0 | S46: =IF(A46<1+Parameters!$D$31,0,INDEX($M$45:$M$80,A46-Parameters!$D$31)) -> 1.9 | T46: =T45+M46-S46 -> 0 | U46: =S46-N46-O46-Q46 -> 1.9 | V46: =V45+U46 -> 1.6 | W46: =(1-Parameters!$D$7)*(C46-E46)+(1-Parameters!$D$8)*(D46+E46) -> 0 | X46: =Parameters!$D$7*(C46-E46)+Parameters!$D$8*Parameters!$D$9*(D46+E46) -> 0 | Y46: =Parameters!$D$8*(1-Parameters!$D$9)*(D46+E46) -> 0 | Z46: =POWER(1/(1+Parameters!$D$32),A46-1)*(M46-N46) -> 0
A47: 3 | B47: =0 -> 0 | C47: =X46+B47 -> 0 | D47: =Y46 -> 0 | E47: =Parameters!$D$6*C47 -> 0 | F47: =IF(Parameters!$D$5=1,E47,0) -> 0 | G47: =Parameters!$D$27*G46+F47 -> 0 | H47: =IF(AND(Parameters!$D$5=1,Parameters!$D$26=1),SUMPRODUCT(--($A$45:A47<A47),--(MOD(A47-$A$45:A47,Parameters!$D$28)=0),$F$45:F47,POWER(Parameters!$D$27,IF(A47-$A$45:A47=0,1,A47-$A$45:A47))),0) -> 0 | I47: =Parameters!$D$23*I46+B47*Parameters!$D$22 -> 0 | J47: =E47*Parameters!$D$14*(1-Parameters!$D$15) -> 0 | K47: =H47*Parameters!$D$29 -> 0 | L47: =I47*Parameters!$D$24 -> 0 | M47: =J47+K47+L47 -> 0 | N47: =C47*Parameters!$D$17+D47*Parameters!$D$18+E47*Parameters!$D$16+I47*Parameters!$D$25+G47*Parameters!$D$30 -> 0 | O47: =0 -> 0 | P47: =M47-N47-O47 -> 0 | Q47: =0 -> 0 | R47: =P47-Q47 -> 0 | S47: =IF(A47<1+Parameters!$D$31,0,INDEX($M$45:$M$80,A47-Parameters!$D$31)) -> 0 | T47: =T46+M47-S47 -> 0 | U47: =S47-N47-O47-Q47 -> 0 | V47: =V46+U47 -> 1.6 | W47: =(1-Parameters!$D$7)*(C47-E47)+(1-Parameters!$D$8)*(D47+E47) -> 0 | X47: =Parameters!$D$7*(C47-E47)+Parameters!$D$8*Parameters!$D$9*(D47+E47) -> 0 | Y47: =Parameters!$D$8*(1-Parameters!$D$9)*(D47+E47) -> 0 | Z47: =POWER(1/(1+Parameters!$D$32),A47-1)*(M47-N47) -> 0
A48: 4 | B48: =0 -> 0 | C48: =X47+B48 -> 0 | D48: =Y47 -> 0 | E48: =Parameters!$D$6*C48 -> 0 | F48: =IF(Parameters!$D$5=1,E48,0) -> 0 | G48: =Parameters!$D$27*G47+F48 -> 0 | H48: =IF(AND(Parameters!$D$5=1,Parameters!$D$26=1),SUMPRODUCT(--($A$45:A48<A48),--(MOD(A48-$A$45:A48,Parameters!$D$28)=0),$F$45:F48,POWER(Parameters!$D$27,IF(A48-$A$45:A48=0,1,A48-$A$45:A48))),0) -> 0 | I48: =Parameters!$D$23*I47+B48*Parameters!$D$22 -> 0 | J48: =E48*Parameters!$D$14*(1-Parameters!$D$15) -> 0 | K48: =H48*Parameters!$D$29 -> 0 | L48: =I48*Parameters!$D$24 -> 0 | M48: =J48+K48+L48 -> 0 | N48: =C48*Parameters!$D$17+D48*Parameters!$D$18+E48*Parameters!$D$16+I48*Parameters!$D$25+G48*Parameters!$D$30 -> 0 | O48: =0 -> 0 | P48: =M48-N48-O48 -> 0 | Q48: =0 -> 0 | R48: =P48-Q48 -> 0 | S48: =IF(A48<1+Parameters!$D$31,0,INDEX($M$45:$M$80,A48-Parameters!$D$31)) -> 0 | T48: =T47+M48-S48 -> 0 | U48: =S48-N48-O48-Q48 -> 0 | V48: =V47+U48 -> 1.6 | W48: =(1-Parameters!$D$7)*(C48-E48)+(1-Parameters!$D$8)*(D48+E48) -> 0 | X48: =Parameters!$D$7*(C48-E48)+Parameters!$D$8*Parameters!$D$9*(D48+E48) -> 0 | Y48: =Parameters!$D$8*(1-Parameters!$D$9)*(D48+E48) -> 0 | Z48: =POWER(1/(1+Parameters!$D$32),A48-1)*(M48-N48) -> 0
A49: 5 | B49: =0 -> 0 | C49: =X48+B49 -> 0 | D49: =Y48 -> 0 | E49: =Parameters!$D$6*C49 -> 0 | F49: =IF(Parameters!$D$5=1,E49,0) -> 0 | G49: =Parameters!$D$27*G48+F49 -> 0 | H49: =IF(AND(Parameters!$D$5=1,Parameters!$D$26=1),SUMPRODUCT(--($A$45:A49<A49),--(MOD(A49-$A$45:A49,Parameters!$D$28)=0),$F$45:F49,POWER(Parameters!$D$27,IF(A49-$A$45:A49=0,1,A49-$A$45:A49))),0) -> 0 | I49: =Parameters!$D$23*I48+B49*Parameters!$D$22 -> 0 | J49: =E49*Parameters!$D$14*(1-Parameters!$D$15) -> 0 | K49: =H49*Parameters!$D$29 -> 0 | L49: =I49*Parameters!$D$24 -> 0 | M49: =J49+K49+L49 -> 0 | N49: =C49*Parameters!$D$17+D49*Parameters!$D$18+E49*Parameters!$D$16+I49*Parameters!$D$25+G49*Parameters!$D$30 -> 0 | O49: =0 -> 0 | P49: =M49-N49-O49 -> 0 | Q49: =0 -> 0 | R49: =P49-Q49 -> 0 | S49: =IF(A49<1+Parameters!$D$31,0,INDEX($M$45:$M$80,A49-Parameters!$D$31)) -> 0 | T49: =T48+M49-S49 -> 0 | U49: =S49-N49-O49-Q49 -> 0 | V49: =V48+U49 -> 1.6 | W49: =(1-Parameters!$D$7)*(C49-E49)+(1-Parameters!$D$8)*(D49+E49) -> 0 | X49: =Parameters!$D$7*(C49-E49)+Parameters!$D$8*Parameters!$D$9*(D49+E49) -> 0 | Y49: =Parameters!$D$8*(1-Parameters!$D$9)*(D49+E49) -> 0 | Z49: =POWER(1/(1+Parameters!$D$32),A49-1)*(M49-N49) -> 0
A50: 6 | B50: =0 -> 0 | C50: =X49+B50 -> 0 | D50: =Y49 -> 0 | E50: =Parameters!$D$6*C50 -> 0 | F50: =IF(Parameters!$D$5=1,E50,0) -> 0 | G50: =Parameters!$D$27*G49+F50 -> 0 | H50: =IF(AND(Parameters!$D$5=1,Parameters!$D$26=1),SUMPRODUCT(--($A$45:A50<A50),--(MOD(A50-$A$45:A50,Parameters!$D$28)=0),$F$45:F50,POWER(Parameters!$D$27,IF(A50-$A$45:A50=0,1,A50-$A$45:A50))),0) -> 0 | I50: =Parameters!$D$23*I49+B50*Parameters!$D$22 -> 0 | J50: =E50*Parameters!$D$14*(1-Parameters!$D$15) -> 0 | K50: =H50*Parameters!$D$29 -> 0 | L50: =I50*Parameters!$D$24 -> 0 | M50: =J50+K50+L50 -> 0 | N50: =C50*Parameters!$D$17+D50*Parameters!$D$18+E50*Parameters!$D$16+I50*Parameters!$D$25+G50*Parameters!$D$30 -> 0 | O50: =0 -> 0 | P50: =M50-N50-O50 -> 0 | Q50: =0 -> 0 | R50: =P50-Q50 -> 0 | S50: =IF(A50<1+Parameters!$D$31,0,INDEX($M$45:$M$80,A50-Parameters!$D$31)) -> 0 | T50: =T49+M50-S50 -> 0 | U50: =S50-N50-O50-Q50 -> 0 | V50: =V49+U50 -> 1.6 | W50: =(1-Parameters!$D$7)*(C50-E50)+(1-Parameters!$D$8)*(D50+E50) -> 0 | X50: =Parameters!$D$7*(C50-E50)+Parameters!$D$8*Parameters!$D$9*(D50+E50) -> 0 | Y50: =Parameters!$D$8*(1-Parameters!$D$9)*(D50+E50) -> 0 | Z50: =POWER(1/(1+Parameters!$D$32),A50-1)*(M50-N50) -> 0
A51: 7 | B51: =0 -> 0 | C51: =X50+B51 -> 0 | D51: =Y50 -> 0 | E51: =Parameters!$D$6*C51 -> 0 | F51: =IF(Parameters!$D$5=1,E51,0) -> 0 | G51: =Parameters!$D$27*G50+F51 -> 0 | H51: =IF(AND(Parameters!$D$5=1,Parameters!$D$26=1),SUMPRODUCT(--($A$45:A51<A51),--(MOD(A51-$A$45:A51,Parameters!$D$28)=0),$F$45:F51,POWER(Parameters!$D$27,IF(A51-$A$45:A51=0,1,A51-$A$45:A51))),0) -> 0 | I51: =Parameters!$D$23*I50+B51*Parameters!$D$22 -> 0 | J51: =E51*Parameters!$D$14*(1-Parameters!$D$15) -> 0 | K51: =H51*Parameters!$D$29 -> 0 | L51: =I51*Parameters!$D$24 -> 0 | M51: =J51+K51+L51 -> 0 | N51: =C51*Parameters!$D$17+D51*Parameters!$D$18+E51*Parameters!$D$16+I51*Parameters!$D$25+G51*Parameters!$D$30 -> 0 | O51: =0 -> 0 | P51: =M51-N51-O51 -> 0 | Q51: =0 -> 0 | R51: =P51-Q51 -> 0 | S51: =IF(A51<1+Parameters!$D$31,0,INDEX($M$45:$M$80,A51-Parameters!$D$31)) -> 0 | T51: =T50+M51-S51 -> 0 | U51: =S51-N51-O51-Q51 -> 0 | V51: =V50+U51 -> 1.6 | W51: =(1-Parameters!$D$7)*(C51-E51)+(1-Parameters!$D$8)*(D51+E51) -> 0 | X51: =Parameters!$D$7*(C51-E51)+Parameters!$D$8*Parameters!$D$9*(D51+E51) -> 0 | Y51: =Parameters!$D$8*(1-Parameters!$D$9)*(D51+E51) -> 0 | Z51: =POWER(1/(1+Parameters!$D$32),A51-1)*(M51-N51) -> 0
A52: 8 | B52: =0 -> 0 | C52: =X51+B52 -> 0 | D52: =Y51 -> 0 | E52: =Parameters!$D$6*C52 -> 0 | F52: =IF(Parameters!$D$5=1,E52,0) -> 0 | G52: =Parameters!$D$27*G51+F52 -> 0 | H52: =IF(AND(Parameters!$D$5=1,Parameters!$D$26=1),SUMPRODUCT(--($A$45:A52<A52),--(MOD(A52-$A$45:A52,Parameters!$D$28)=0),$F$45:F52,POWER(Parameters!$D$27,IF(A52-$A$45:A52=0,1,A52-$A$45:A52))),0) -> 0 | I52: =Parameters!$D$23*I51+B52*Parameters!$D$22 -> 0 | J52: =E52*Parameters!$D$14*(1-Parameters!$D$15) -> 0 | K52: =H52*Parameters!$D$29 -> 0 | L52: =I52*Parameters!$D$24 -> 0 | M52: =J52+K52+L52 -> 0 | N52: =C52*Parameters!$D$17+D52*Parameters!$D$18+E52*Parameters!$D$16+I52*Parameters!$D$25+G52*Parameters!$D$30 -> 0 | O52: =0 -> 0 | P52: =M52-N52-O52 -> 0 | Q52: =0 -> 0 | R52: =P52-Q52 -> 0 | S52: =IF(A52<1+Parameters!$D$31,0,INDEX($M$45:$M$80,A52-Parameters!$D$31)) -> 0 | T52: =T51+M52-S52 -> 0 | U52: =S52-N52-O52-Q52 -> 0 | V52: =V51+U52 -> 1.6 | W52: =(1-Parameters!$D$7)*(C52-E52)+(1-Parameters!$D$8)*(D52+E52) -> 0 | X52: =Parameters!$D$7*(C52-E52)+Parameters!$D$8*Parameters!$D$9*(D52+E52) -> 0 | Y52: =Parameters!$D$8*(1-Parameters!$D$9)*(D52+E52) -> 0 | Z52: =POWER(1/(1+Parameters!$D$32),A52-1)*(M52-N52) -> 0
A53: 9 | B53: =0 -> 0 | C53: =X52+B53 -> 0 | D53: =Y52 -> 0 | E53: =Parameters!$D$6*C53 -> 0 | F53: =IF(Parameters!$D$5=1,E53,0) -> 0 | G53: =Parameters!$D$27*G52+F53 -> 0 | H53: =IF(AND(Parameters!$D$5=1,Parameters!$D$26=1),SUMPRODUCT(--($A$45:A53<A53),--(MOD(A53-$A$45:A53,Parameters!$D$28)=0),$F$45:F53,POWER(Parameters!$D$27,IF(A53-$A$45:A53=0,1,A53-$A$45:A53))),0) -> 0 | I53: =Parameters!$D$23*I52+B53*Parameters!$D$22 -> 0 | J53: =E53*Parameters!$D$14*(1-Parameters!$D$15) -> 0 | K53: =H53*Parameters!$D$29 -> 0 | L53: =I53*Parameters!$D$24 -> 0 | M53: =J53+K53+L53 -> 0 | N53: =C53*Parameters!$D$17+D53*Parameters!$D$18+E53*Parameters!$D$16+I53*Parameters!$D$25+G53*Parameters!$D$30 -> 0 | O53: =0 -> 0 | P53: =M53-N53-O53 -> 0 | Q53: =0 -> 0 | R53: =P53-Q53 -> 0 | S53: =IF(A53<1+Parameters!$D$31,0,INDEX($M$45:$M$80,A53-Parameters!$D$31)) -> 0 | T53: =T52+M53-S53 -> 0 | U53: =S53-N53-O53-Q53 -> 0 | V53: =V52+U53 -> 1.6 | W53: =(1-Parameters!$D$7)*(C53-E53)+(1-Parameters!$D$8)*(D53+E53) -> 0 | X53: =Parameters!$D$7*(C53-E53)+Parameters!$D$8*Parameters!$D$9*(D53+E53) -> 0 | Y53: =Parameters!$D$8*(1-Parameters!$D$9)*(D53+E53) -> 0 | Z53: =POWER(1/(1+Parameters!$D$32),A53-1)*(M53-N53) -> 0
A54: 10 | B54: =0 -> 0 | C54: =X53+B54 -> 0 | D54: =Y53 -> 0 | E54: =Parameters!$D$6*C54 -> 0 | F54: =IF(Parameters!$D$5=1,E54,0) -> 0 | G54: =Parameters!$D$27*G53+F54 -> 0 | H54: =IF(AND(Parameters!$D$5=1,Parameters!$D$26=1),SUMPRODUCT(--($A$45:A54<A54),--(MOD(A54-$A$45:A54,Parameters!$D$28)=0),$F$45:F54,POWER(Parameters!$D$27,IF(A54-$A$45:A54=0,1,A54-$A$45:A54))),0) -> 0 | I54: =Parameters!$D$23*I53+B54*Parameters!$D$22 -> 0 | J54: =E54*Parameters!$D$14*(1-Parameters!$D$15) -> 0 | K54: =H54*Parameters!$D$29 -> 0 | L54: =I54*Parameters!$D$24 -> 0 | M54: =J54+K54+L54 -> 0 | N54: =C54*Parameters!$D$17+D54*Parameters!$D$18+E54*Parameters!$D$16+I54*Parameters!$D$25+G54*Parameters!$D$30 -> 0 | O54: =0 -> 0 | P54: =M54-N54-O54 -> 0 | Q54: =0 -> 0 | R54: =P54-Q54 -> 0 | S54: =IF(A54<1+Parameters!$D$31,0,INDEX($M$45:$M$80,A54-Parameters!$D$31)) -> 0 | T54: =T53+M54-S54 -> 0 | U54: =S54-N54-O54-Q54 -> 0 | V54: =V53+U54 -> 1.6 | W54: =(1-Parameters!$D$7)*(C54-E54)+(1-Parameters!$D$8)*(D54+E54) -> 0 | X54: =Parameters!$D$7*(C54-E54)+Parameters!$D$8*Parameters!$D$9*(D54+E54) -> 0 | Y54: =Parameters!$D$8*(1-Parameters!$D$9)*(D54+E54) -> 0 | Z54: =POWER(1/(1+Parameters!$D$32),A54-1)*(M54-N54) -> 0
A55: 11 | B55: =0 -> 0 | C55: =X54+B55 -> 0 | D55: =Y54 -> 0 | E55: =Parameters!$D$6*C55 -> 0 | F55: =IF(Parameters!$D$5=1,E55,0) -> 0 | G55: =Parameters!$D$27*G54+F55 -> 0 | H55: =IF(AND(Parameters!$D$5=1,Parameters!$D$26=1),SUMPRODUCT(--($A$45:A55<A55),--(MOD(A55-$A$45:A55,Parameters!$D$28)=0),$F$45:F55,POWER(Parameters!$D$27,IF(A55-$A$45:A55=0,1,A55-$A$45:A55))),0) -> 0 | I55: =Parameters!$D$23*I54+B55*Parameters!$D$22 -> 0 | J55: =E55*Parameters!$D$14*(1-Parameters!$D$15) -> 0 | K55: =H55*Parameters!$D$29 -> 0 | L55: =I55*Parameters!$D$24 -> 0 | M55: =J55+K55+L55 -> 0 | N55: =C55*Parameters!$D$17+D55*Parameters!$D$18+E55*Parameters!$D$16+I55*Parameters!$D$25+G55*Parameters!$D$30 -> 0 | O55: =0 -> 0 | P55: =M55-N55-O55 -> 0 | Q55: =0 -> 0 | R55: =P55-Q55 -> 0 | S55: =IF(A55<1+Parameters!$D$31,0,INDEX($M$45:$M$80,A55-Parameters!$D$31)) -> 0 | T55: =T54+M55-S55 -> 0 | U55: =S55-N55-O55-Q55 -> 0 | V55: =V54+U55 -> 1.6 | W55: =(1-Parameters!$D$7)*(C55-E55)+(1-Parameters!$D$8)*(D55+E55) -> 0 | X55: =Parameters!$D$7*(C55-E55)+Parameters!$D$8*Parameters!$D$9*(D55+E55) -> 0 | Y55: =Parameters!$D$8*(1-Parameters!$D$9)*(D55+E55) -> 0 | Z55: =POWER(1/(1+Parameters!$D$32),A55-1)*(M55-N55) -> 0
A56: 12 | B56: =0 -> 0 | C56: =X55+B56 -> 0 | D56: =Y55 -> 0 | E56: =Parameters!$D$6*C56 -> 0 | F56: =IF(Parameters!$D$5=1,E56,0) -> 0 | G56: =Parameters!$D$27*G55+F56 -> 0 | H56: =IF(AND(Parameters!$D$5=1,Parameters!$D$26=1),SUMPRODUCT(--($A$45:A56<A56),--(MOD(A56-$A$45:A56,Parameters!$D$28)=0),$F$45:F56,POWER(Parameters!$D$27,IF(A56-$A$45:A56=0,1,A56-$A$45:A56))),0) -> 0 | I56: =Parameters!$D$23*I55+B56*Parameters!$D$22 -> 0 | J56: =E56*Parameters!$D$14*(1-Parameters!$D$15) -> 0 | K56: =H56*Parameters!$D$29 -> 0 | L56: =I56*Parameters!$D$24 -> 0 | M56: =J56+K56+L56 -> 0 | N56: =C56*Parameters!$D$17+D56*Parameters!$D$18+E56*Parameters!$D$16+I56*Parameters!$D$25+G56*Parameters!$D$30 -> 0 | O56: =0 -> 0 | P56: =M56-N56-O56 -> 0 | Q56: =0 -> 0 | R56: =P56-Q56 -> 0 | S56: =IF(A56<1+Parameters!$D$31,0,INDEX($M$45:$M$80,A56-Parameters!$D$31)) -> 0 | T56: =T55+M56-S56 -> 0 | U56: =S56-N56-O56-Q56 -> 0 | V56: =V55+U56 -> 1.6 | W56: =(1-Parameters!$D$7)*(C56-E56)+(1-Parameters!$D$8)*(D56+E56) -> 0 | X56: =Parameters!$D$7*(C56-E56)+Parameters!$D$8*Parameters!$D$9*(D56+E56) -> 0 | Y56: =Parameters!$D$8*(1-Parameters!$D$9)*(D56+E56) -> 0 | Z56: =POWER(1/(1+Parameters!$D$32),A56-1)*(M56-N56) -> 0
A57: 13 | B57: =0 -> 0 | C57: =X56+B57 -> 0 | D57: =Y56 -> 0 | E57: =Parameters!$D$6*C57 -> 0 | F57: =IF(Parameters!$D$5=1,E57,0) -> 0 | G57: =Parameters!$D$27*G56+F57 -> 0 | H57: =IF(AND(Parameters!$D$5=1,Parameters!$D$26=1),SUMPRODUCT(--($A$45:A57<A57),--(MOD(A57-$A$45:A57,Parameters!$D$28)=0),$F$45:F57,POWER(Parameters!$D$27,IF(A57-$A$45:A57=0,1,A57-$A$45:A57))),0) -> 0 | I57: =Parameters!$D$23*I56+B57*Parameters!$D$22 -> 0 | J57: =E57*Parameters!$D$14*(1-Parameters!$D$15) -> 0 | K57: =H57*Parameters!$D$29 -> 0 | L57: =I57*Parameters!$D$24 -> 0 | M57: =J57+K57+L57 -> 0 | N57: =C57*Parameters!$D$17+D57*Parameters!$D$18+E57*Parameters!$D$16+I57*Parameters!$D$25+G57*Parameters!$D$30 -> 0 | O57: =0 -> 0 | P57: =M57-N57-O57 -> 0 | Q57: =0 -> 0 | R57: =P57-Q57 -> 0 | S57: =IF(A57<1+Parameters!$D$31,0,INDEX($M$45:$M$80,A57-Parameters!$D$31)) -> 0 | T57: =T56+M57-S57 -> 0 | U57: =S57-N57-O57-Q57 -> 0 | V57: =V56+U57 -> 1.6 | W57: =(1-Parameters!$D$7)*(C57-E57)+(1-Parameters!$D$8)*(D57+E57) -> 0 | X57: =Parameters!$D$7*(C57-E57)+Parameters!$D$8*Parameters!$D$9*(D57+E57) -> 0 | Y57: =Parameters!$D$8*(1-Parameters!$D$9)*(D57+E57) -> 0 | Z57: =POWER(1/(1+Parameters!$D$32),A57-1)*(M57-N57) -> 0
... A80: 36 | B80: =0 -> 0 | C80: =X79+B80 -> 0 | D80: =Y79 -> 0 | E80: =Parameters!$D$6*C80 -> 0 | F80: =IF(Parameters!$D$5=1,E80,0) -> 0 | G80: =Parameters!$D$27*G79+F80 -> 0 | H80: =IF(AND(Parameters!$D$5=1,Parameters!$D$26=1),SUMPRODUCT(--($A$45:A80<A80),--(MOD(A80-$A$45:A80,Parameters!$D$28)=0),$F$45:F80,POWER(Parameters!$D$27,IF(A80-$A$45:A80=0,1,A80-$A$45:A80))),0) -> 0 | I80: =Parameters!$D$23*I79+B80*Parameters!$D$22 -> 0 | J80: =E80*Parameters!$D$14*(1-Parameters!$D$15) -> 0 | K80: =H80*Parameters!$D$29 -> 0 | L80: =I80*Parameters!$D$24 -> 0 | M80: =J80+K80+L80 -> 0 | N80: =C80*Parameters!$D$17+D80*Parameters!$D$18+E80*Parameters!$D$16+I80*Parameters!$D$25+G80*Parameters!$D$30 -> 0 | O80: =0 -> 0 | P80: =M80-N80-O80 -> 0 | Q80: =0 -> 0 | R80: =P80-Q80 -> 0 | S80: =IF(A80<1+Parameters!$D$31,0,INDEX($M$45:$M$80,A80-Parameters!$D$31)) -> 0 | T80: =T79+M80-S80 -> 0 | U80: =S80-N80-O80-Q80 -> 0 | V80: =V79+U80 -> 1.6 | W80: =(1-Parameters!$D$7)*(C80-E80)+(1-Parameters!$D$8)*(D80+E80) -> 0 | X80: =Parameters!$D$7*(C80-E80)+Parameters!$D$8*Parameters!$D$9*(D80+E80) -> 0 | Y80: =Parameters!$D$8*(1-Parameters!$D$9)*(D80+E80) -> 0 | Z80: =POWER(1/(1+Parameters!$D$32),A80-1)*(M80-N80) -> 0

Sheet S2
A1: S2 — Retain after first lead only
A2: All parameters are illustrative. Top block: calendar cohorts. Lower block: one acquired owner, no CAC/fixed cost, for customer-value calculation.
A4: Month | B4: Acquired | C4: E eligible | D4: M completed active | E4: Payable events | F4: New policies | G4: Active policies | H4: Renewed policies | I4: Billed subscribers | J4: Initial revenue | K4: Renewal revenue | L4: Software revenue | M4: Total revenue | N4: Variable cost | O4: Acquisition cost | P4: Contribution | Q4: Fixed cost | R4: Operating result | S4: Cash receipts | T4: Receivables | U4: Cash surplus | V4: Cumulative cash | W4: Churned opportunity owners | X4: Next E | Y4: Next M | Z4: Discounted contribution before CAC
A5: 1 | B5: =Parameters!$E$20 -> 1000 | C5: =B5 -> 1000 | D5: =0 -> 0 | E5: =Parameters!$E$6*C5 -> 100 | F5: =IF(Parameters!$E$5=1,E5,0) -> 0 | G5: =F5 -> 0 | H5: =IF(AND(Parameters!$E$5=1,Parameters!$E$26=1),SUMPRODUCT(--($A$5:A5<A5),--(MOD(A5-$A$5:A5,Parameters!$E$28)=0),$F$5:F5,POWER(Parameters!$E$27,IF(A5-$A$5:A5=0,1,A5-$A$5:A5))),0) -> 0 | I5: =B5*Parameters!$E$22 -> 0 | J5: =E5*Parameters!$E$14*(1-Parameters!$E$15) -> 1900 | K5: =H5*Parameters!$E$29 -> 0 | L5: =I5*Parameters!$E$24 -> 0 | M5: =J5+K5+L5 -> 1900 | N5: =C5*Parameters!$E$17+D5*Parameters!$E$18+E5*Parameters!$E$16+I5*Parameters!$E$25+G5*Parameters!$E$30 -> 300 | O5: =B5*Parameters!$E$19 -> 4000 | P5: =M5-N5-O5 -> -2400 | Q5: =Parameters!$E$21 -> 1000 | R5: =P5-Q5 -> -3400 | S5: =IF(A5<1+Parameters!$E$31,0,INDEX($M$5:$M$40,A5-Parameters!$E$31)) -> 0 | T5: =M5-S5 -> 1900 | U5: =S5-N5-O5-Q5 -> -5300 | V5: =U5 -> -5300 | W5: =(1-Parameters!$E$7)*(C5-E5)+(1-Parameters!$E$8)*(D5+E5) -> 920 | X5: =Parameters!$E$7*(C5-E5)+Parameters!$E$8*Parameters!$E$9*(D5+E5) -> 0 | Y5: =Parameters!$E$8*(1-Parameters!$E$9)*(D5+E5) -> 80 | Z5: =POWER(1/(1+Parameters!$E$32),A5-1)*(M5-N5) -> 1600
A6: 2 | B6: =Parameters!$E$20 -> 1000 | C6: =X5+B6 -> 1000 | D6: =Y5 -> 80 | E6: =Parameters!$E$6*C6 -> 100 | F6: =IF(Parameters!$E$5=1,E6,0) -> 0 | G6: =Parameters!$E$27*G5+F6 -> 0 | H6: =IF(AND(Parameters!$E$5=1,Parameters!$E$26=1),SUMPRODUCT(--($A$5:A6<A6),--(MOD(A6-$A$5:A6,Parameters!$E$28)=0),$F$5:F6,POWER(Parameters!$E$27,IF(A6-$A$5:A6=0,1,A6-$A$5:A6))),0) -> 0 | I6: =Parameters!$E$23*I5+B6*Parameters!$E$22 -> 0 | J6: =E6*Parameters!$E$14*(1-Parameters!$E$15) -> 1900 | K6: =H6*Parameters!$E$29 -> 0 | L6: =I6*Parameters!$E$24 -> 0 | M6: =J6+K6+L6 -> 1900 | N6: =C6*Parameters!$E$17+D6*Parameters!$E$18+E6*Parameters!$E$16+I6*Parameters!$E$25+G6*Parameters!$E$30 -> 324 | O6: =B6*Parameters!$E$19 -> 4000 | P6: =M6-N6-O6 -> -2424 | Q6: =Parameters!$E$21 -> 1000 | R6: =P6-Q6 -> -3424 | S6: =IF(A6<1+Parameters!$E$31,0,INDEX($M$5:$M$40,A6-Parameters!$E$31)) -> 1900 | T6: =T5+M6-S6 -> 1900 | U6: =S6-N6-O6-Q6 -> -3424 | V6: =V5+U6 -> -8724 | W6: =(1-Parameters!$E$7)*(C6-E6)+(1-Parameters!$E$8)*(D6+E6) -> 936 | X6: =Parameters!$E$7*(C6-E6)+Parameters!$E$8*Parameters!$E$9*(D6+E6) -> 0 | Y6: =Parameters!$E$8*(1-Parameters!$E$9)*(D6+E6) -> 144 | Z6: =POWER(1/(1+Parameters!$E$32),A6-1)*(M6-N6) -> 1560.396
A7: 3 | B7: =Parameters!$E$20 -> 1000 | C7: =X6+B7 -> 1000 | D7: =Y6 -> 144 | E7: =Parameters!$E$6*C7 -> 100 | F7: =IF(Parameters!$E$5=1,E7,0) -> 0 | G7: =Parameters!$E$27*G6+F7 -> 0 | H7: =IF(AND(Parameters!$E$5=1,Parameters!$E$26=1),SUMPRODUCT(--($A$5:A7<A7),--(MOD(A7-$A$5:A7,Parameters!$E$28)=0),$F$5:F7,POWER(Parameters!$E$27,IF(A7-$A$5:A7=0,1,A7-$A$5:A7))),0) -> 0 | I7: =Parameters!$E$23*I6+B7*Parameters!$E$22 -> 0 | J7: =E7*Parameters!$E$14*(1-Parameters!$E$15) -> 1900 | K7: =H7*Parameters!$E$29 -> 0 | L7: =I7*Parameters!$E$24 -> 0 | M7: =J7+K7+L7 -> 1900 | N7: =C7*Parameters!$E$17+D7*Parameters!$E$18+E7*Parameters!$E$16+I7*Parameters!$E$25+G7*Parameters!$E$30 -> 343.2 | O7: =B7*Parameters!$E$19 -> 4000 | P7: =M7-N7-O7 -> -2443.2 | Q7: =Parameters!$E$21 -> 1000 | R7: =P7-Q7 -> -3443.2 | S7: =IF(A7<1+Parameters!$E$31,0,INDEX($M$5:$M$40,A7-Parameters!$E$31)) -> 1900 | T7: =T6+M7-S7 -> 1900 | U7: =S7-N7-O7-Q7 -> -3443.2 | V7: =V6+U7 -> -12167.2 | W7: =(1-Parameters!$E$7)*(C7-E7)+(1-Parameters!$E$8)*(D7+E7) -> 948.8 | X7: =Parameters!$E$7*(C7-E7)+Parameters!$E$8*Parameters!$E$9*(D7+E7) -> 0 | Y7: =Parameters!$E$8*(1-Parameters!$E$9)*(D7+E7) -> 195.2 | Z7: =POWER(1/(1+Parameters!$E$32),A7-1)*(M7-N7) -> 1526.1249
A8: 4 | B8: =Parameters!$E$20 -> 1000 | C8: =X7+B8 -> 1000 | D8: =Y7 -> 195.2 | E8: =Parameters!$E$6*C8 -> 100 | F8: =IF(Parameters!$E$5=1,E8,0) -> 0 | G8: =Parameters!$E$27*G7+F8 -> 0 | H8: =IF(AND(Parameters!$E$5=1,Parameters!$E$26=1),SUMPRODUCT(--($A$5:A8<A8),--(MOD(A8-$A$5:A8,Parameters!$E$28)=0),$F$5:F8,POWER(Parameters!$E$27,IF(A8-$A$5:A8=0,1,A8-$A$5:A8))),0) -> 0 | I8: =Parameters!$E$23*I7+B8*Parameters!$E$22 -> 0 | J8: =E8*Parameters!$E$14*(1-Parameters!$E$15) -> 1900 | K8: =H8*Parameters!$E$29 -> 0 | L8: =I8*Parameters!$E$24 -> 0 | M8: =J8+K8+L8 -> 1900 | N8: =C8*Parameters!$E$17+D8*Parameters!$E$18+E8*Parameters!$E$16+I8*Parameters!$E$25+G8*Parameters!$E$30 -> 358.56 | O8: =B8*Parameters!$E$19 -> 4000 | P8: =M8-N8-O8 -> -2458.56 | Q8: =Parameters!$E$21 -> 1000 | R8: =P8-Q8 -> -3458.56 | S8: =IF(A8<1+Parameters!$E$31,0,INDEX($M$5:$M$40,A8-Parameters!$E$31)) -> 1900 | T8: =T7+M8-S8 -> 1900 | U8: =S8-N8-O8-Q8 -> -3458.56 | V8: =V7+U8 -> -15625.76 | W8: =(1-Parameters!$E$7)*(C8-E8)+(1-Parameters!$E$8)*(D8+E8) -> 959.04 | X8: =Parameters!$E$7*(C8-E8)+Parameters!$E$8*Parameters!$E$9*(D8+E8) -> 0 | Y8: =Parameters!$E$8*(1-Parameters!$E$9)*(D8+E8) -> 236.16 | Z8: =POWER(1/(1+Parameters!$E$32),A8-1)*(M8-N8) -> 1496.1065
A9: 5 | B9: =Parameters!$E$20 -> 1000 | C9: =X8+B9 -> 1000 | D9: =Y8 -> 236.16 | E9: =Parameters!$E$6*C9 -> 100 | F9: =IF(Parameters!$E$5=1,E9,0) -> 0 | G9: =Parameters!$E$27*G8+F9 -> 0 | H9: =IF(AND(Parameters!$E$5=1,Parameters!$E$26=1),SUMPRODUCT(--($A$5:A9<A9),--(MOD(A9-$A$5:A9,Parameters!$E$28)=0),$F$5:F9,POWER(Parameters!$E$27,IF(A9-$A$5:A9=0,1,A9-$A$5:A9))),0) -> 0 | I9: =Parameters!$E$23*I8+B9*Parameters!$E$22 -> 0 | J9: =E9*Parameters!$E$14*(1-Parameters!$E$15) -> 1900 | K9: =H9*Parameters!$E$29 -> 0 | L9: =I9*Parameters!$E$24 -> 0 | M9: =J9+K9+L9 -> 1900 | N9: =C9*Parameters!$E$17+D9*Parameters!$E$18+E9*Parameters!$E$16+I9*Parameters!$E$25+G9*Parameters!$E$30 -> 370.848 | O9: =B9*Parameters!$E$19 -> 4000 | P9: =M9-N9-O9 -> -2470.848 | Q9: =Parameters!$E$21 -> 1000 | R9: =P9-Q9 -> -3470.848 | S9: =IF(A9<1+Parameters!$E$31,0,INDEX($M$5:$M$40,A9-Parameters!$E$31)) -> 1900 | T9: =T8+M9-S9 -> 1900 | U9: =S9-N9-O9-Q9 -> -3470.848 | V9: =V8+U9 -> -19096.608 | W9: =(1-Parameters!$E$7)*(C9-E9)+(1-Parameters!$E$8)*(D9+E9) -> 967.232 | X9: =Parameters!$E$7*(C9-E9)+Parameters!$E$8*Parameters!$E$9*(D9+E9) -> 0 | Y9: =Parameters!$E$8*(1-Parameters!$E$9)*(D9+E9) -> 268.928 | Z9: =POWER(1/(1+Parameters!$E$32),A9-1)*(M9-N9) -> 1469.485
A10: 6 | B10: =Parameters!$E$20 -> 1000 | C10: =X9+B10 -> 1000 | D10: =Y9 -> 268.928 | E10: =Parameters!$E$6*C10 -> 100 | F10: =IF(Parameters!$E$5=1,E10,0) -> 0 | G10: =Parameters!$E$27*G9+F10 -> 0 | H10: =IF(AND(Parameters!$E$5=1,Parameters!$E$26=1),SUMPRODUCT(--($A$5:A10<A10),--(MOD(A10-$A$5:A10,Parameters!$E$28)=0),$F$5:F10,POWER(Parameters!$E$27,IF(A10-$A$5:A10=0,1,A10-$A$5:A10))),0) -> 0 | I10: =Parameters!$E$23*I9+B10*Parameters!$E$22 -> 0 | J10: =E10*Parameters!$E$14*(1-Parameters!$E$15) -> 1900 | K10: =H10*Parameters!$E$29 -> 0 | L10: =I10*Parameters!$E$24 -> 0 | M10: =J10+K10+L10 -> 1900 | N10: =C10*Parameters!$E$17+D10*Parameters!$E$18+E10*Parameters!$E$16+I10*Parameters!$E$25+G10*Parameters!$E$30 -> 380.6784 | O10: =B10*Parameters!$E$19 -> 4000 | P10: =M10-N10-O10 -> -2480.6784 | Q10: =Parameters!$E$21 -> 1000 | R10: =P10-Q10 -> -3480.6784 | S10: =IF(A10<1+Parameters!$E$31,0,INDEX($M$5:$M$40,A10-Parameters!$E$31)) -> 1900 | T10: =T9+M10-S10 -> 1900 | U10: =S10-N10-O10-Q10 -> -3480.6784 | V10: =V9+U10 -> -22577.286 | W10: =(1-Parameters!$E$7)*(C10-E10)+(1-Parameters!$E$8)*(D10+E10) -> 973.7856 | X10: =Parameters!$E$7*(C10-E10)+Parameters!$E$8*Parameters!$E$9*(D10+E10) -> 0 | Y10: =Parameters!$E$8*(1-Parameters!$E$9)*(D10+E10) -> 295.1424 | Z10: =POWER(1/(1+Parameters!$E$32),A10-1)*(M10-N10) -> 1445.5824
A11: 7 | B11: =Parameters!$E$20 -> 1000 | C11: =X10+B11 -> 1000 | D11: =Y10 -> 295.1424 | E11: =Parameters!$E$6*C11 -> 100 | F11: =IF(Parameters!$E$5=1,E11,0) -> 0 | G11: =Parameters!$E$27*G10+F11 -> 0 | H11: =IF(AND(Parameters!$E$5=1,Parameters!$E$26=1),SUMPRODUCT(--($A$5:A11<A11),--(MOD(A11-$A$5:A11,Parameters!$E$28)=0),$F$5:F11,POWER(Parameters!$E$27,IF(A11-$A$5:A11=0,1,A11-$A$5:A11))),0) -> 0 | I11: =Parameters!$E$23*I10+B11*Parameters!$E$22 -> 0 | J11: =E11*Parameters!$E$14*(1-Parameters!$E$15) -> 1900 | K11: =H11*Parameters!$E$29 -> 0 | L11: =I11*Parameters!$E$24 -> 0 | M11: =J11+K11+L11 -> 1900 | N11: =C11*Parameters!$E$17+D11*Parameters!$E$18+E11*Parameters!$E$16+I11*Parameters!$E$25+G11*Parameters!$E$30 -> 388.54272 | O11: =B11*Parameters!$E$19 -> 4000 | P11: =M11-N11-O11 -> -2488.5427 | Q11: =Parameters!$E$21 -> 1000 | R11: =P11-Q11 -> -3488.5427 | S11: =IF(A11<1+Parameters!$E$31,0,INDEX($M$5:$M$40,A11-Parameters!$E$31)) -> 1900 | T11: =T10+M11-S11 -> 1900 | U11: =S11-N11-O11-Q11 -> -3488.5427 | V11: =V10+U11 -> -26065.829 | W11: =(1-Parameters!$E$7)*(C11-E11)+(1-Parameters!$E$8)*(D11+E11) -> 979.02848 | X11: =Parameters!$E$7*(C11-E11)+Parameters!$E$8*Parameters!$E$9*(D11+E11) -> 0 | Y11: =Parameters!$E$8*(1-Parameters!$E$9)*(D11+E11) -> 316.11392 | Z11: =POWER(1/(1+Parameters!$E$32),A11-1)*(M11-N11) -> 1423.8611
A12: 8 | B12: =Parameters!$E$20 -> 1000 | C12: =X11+B12 -> 1000 | D12: =Y11 -> 316.11392 | E12: =Parameters!$E$6*C12 -> 100 | F12: =IF(Parameters!$E$5=1,E12,0) -> 0 | G12: =Parameters!$E$27*G11+F12 -> 0 | H12: =IF(AND(Parameters!$E$5=1,Parameters!$E$26=1),SUMPRODUCT(--($A$5:A12<A12),--(MOD(A12-$A$5:A12,Parameters!$E$28)=0),$F$5:F12,POWER(Parameters!$E$27,IF(A12-$A$5:A12=0,1,A12-$A$5:A12))),0) -> 0 | I12: =Parameters!$E$23*I11+B12*Parameters!$E$22 -> 0 | J12: =E12*Parameters!$E$14*(1-Parameters!$E$15) -> 1900 | K12: =H12*Parameters!$E$29 -> 0 | L12: =I12*Parameters!$E$24 -> 0 | M12: =J12+K12+L12 -> 1900 | N12: =C12*Parameters!$E$17+D12*Parameters!$E$18+E12*Parameters!$E$16+I12*Parameters!$E$25+G12*Parameters!$E$30 -> 394.83418 | O12: =B12*Parameters!$E$19 -> 4000 | P12: =M12-N12-O12 -> -2494.8342 | Q12: =Parameters!$E$21 -> 1000 | R12: =P12-Q12 -> -3494.8342 | S12: =IF(A12<1+Parameters!$E$31,0,INDEX($M$5:$M$40,A12-Parameters!$E$31)) -> 1900 | T12: =T11+M12-S12 -> 1900 | U12: =S12-N12-O12-Q12 -> -3494.8342 | V12: =V11+U12 -> -29560.663 | W12: =(1-Parameters!$E$7)*(C12-E12)+(1-Parameters!$E$8)*(D12+E12) -> 983.22278 | X12: =Parameters!$E$7*(C12-E12)+Parameters!$E$8*Parameters!$E$9*(D12+E12) -> 0 | Y12: =Parameters!$E$8*(1-Parameters!$E$9)*(D12+E12) -> 332.89114 | Z12: =POWER(1/(1+Parameters!$E$32),A12-1)*(M12-N12) -> 1403.8953
A13: 9 | B13: =Parameters!$E$20 -> 1000 | C13: =X12+B13 -> 1000 | D13: =Y12 -> 332.89114 | E13: =Parameters!$E$6*C13 -> 100 | F13: =IF(Parameters!$E$5=1,E13,0) -> 0 | G13: =Parameters!$E$27*G12+F13 -> 0 | H13: =IF(AND(Parameters!$E$5=1,Parameters!$E$26=1),SUMPRODUCT(--($A$5:A13<A13),--(MOD(A13-$A$5:A13,Parameters!$E$28)=0),$F$5:F13,POWER(Parameters!$E$27,IF(A13-$A$5:A13=0,1,A13-$A$5:A13))),0) -> 0 | I13: =Parameters!$E$23*I12+B13*Parameters!$E$22 -> 0 | J13: =E13*Parameters!$E$14*(1-Parameters!$E$15) -> 1900 | K13: =H13*Parameters!$E$29 -> 0 | L13: =I13*Parameters!$E$24 -> 0 | M13: =J13+K13+L13 -> 1900 | N13: =C13*Parameters!$E$17+D13*Parameters!$E$18+E13*Parameters!$E$16+I13*Parameters!$E$25+G13*Parameters!$E$30 -> 399.86734 | O13: =B13*Parameters!$E$19 -> 4000 | P13: =M13-N13-O13 -> -2499.8673 | Q13: =Parameters!$E$21 -> 1000 | R13: =P13-Q13 -> -3499.8673 | S13: =IF(A13<1+Parameters!$E$31,0,INDEX($M$5:$M$40,A13-Parameters!$E$31)) -> 1900 | T13: =T12+M13-S13 -> 1900 | U13: =S13-N13-O13-Q13 -> -3499.8673 | V13: =V12+U13 -> -33060.531 | W13: =(1-Parameters!$E$7)*(C13-E13)+(1-Parameters!$E$8)*(D13+E13) -> 986.57823 | X13: =Parameters!$E$7*(C13-E13)+Parameters!$E$8*Parameters!$E$9*(D13+E13) -> 0 | Y13: =Parameters!$E$8*(1-Parameters!$E$9)*(D13+E13) -> 346.31291 | Z13: =POWER(1/(1+Parameters!$E$32),A13-1)*(M13-N13) -> 1385.3473
A14: 10 | B14: =Parameters!$E$20 -> 1000 | C14: =X13+B14 -> 1000 | D14: =Y13 -> 346.31291 | E14: =Parameters!$E$6*C14 -> 100 | F14: =IF(Parameters!$E$5=1,E14,0) -> 0 | G14: =Parameters!$E$27*G13+F14 -> 0 | H14: =IF(AND(Parameters!$E$5=1,Parameters!$E$26=1),SUMPRODUCT(--($A$5:A14<A14),--(MOD(A14-$A$5:A14,Parameters!$E$28)=0),$F$5:F14,POWER(Parameters!$E$27,IF(A14-$A$5:A14=0,1,A14-$A$5:A14))),0) -> 0 | I14: =Parameters!$E$23*I13+B14*Parameters!$E$22 -> 0 | J14: =E14*Parameters!$E$14*(1-Parameters!$E$15) -> 1900 | K14: =H14*Parameters!$E$29 -> 0 | L14: =I14*Parameters!$E$24 -> 0 | M14: =J14+K14+L14 -> 1900 | N14: =C14*Parameters!$E$17+D14*Parameters!$E$18+E14*Parameters!$E$16+I14*Parameters!$E$25+G14*Parameters!$E$30 -> 403.89387 | O14: =B14*Parameters!$E$19 -> 4000 | P14: =M14-N14-O14 -> -2503.8939 | Q14: =Parameters!$E$21 -> 1000 | R14: =P14-Q14 -> -3503.8939 | S14: =IF(A14<1+Parameters!$E$31,0,INDEX($M$5:$M$40,A14-Parameters!$E$31)) -> 1900 | T14: =T13+M14-S14 -> 1900 | U14: =S14-N14-O14-Q14 -> -3503.8939 | V14: =V13+U14 -> -36564.425 | W14: =(1-Parameters!$E$7)*(C14-E14)+(1-Parameters!$E$8)*(D14+E14) -> 989.26258 | X14: =Parameters!$E$7*(C14-E14)+Parameters!$E$8*Parameters!$E$9*(D14+E14) -> 0 | Y14: =Parameters!$E$8*(1-Parameters!$E$9)*(D14+E14) -> 357.05033 | Z14: =POWER(1/(1+Parameters!$E$32),A14-1)*(M14-N14) -> 1367.9494
